Workbook

Sheet Welcome
B2: YMCA Annual Organisational Health Assessment Tool
B3: Guidance
B6: Purpose
B7: The YMCA Organisational Health Assessment Tool is designed to support your YMCA in assessing how your organisation performs across various categories, from an organisational sustainability perspective. You can use this form in your YMCA, regardless of size or experience. If you share the information filled in this tool with your Area Alliance and World YMCA, this will also provide very valuable information that will support the mission of your Area Alliance and World YMCA when it comes to Movement Strengthening efforts. The information collected will help identify strengths and areas for improvement and develop organisational development plans so you can identify ways to better serve your community, for the longer-term. This Health Assessment is a joint tool that will be used by all Area Alliances and World YMCA. This way, it will simplify the process for the entire Movement by replacing numerous types of health assessments into just one. This tool will be continuously improved based on feedback. Please note: The purpose of the assessment tool is to provide guidance and orientation to YMCA leadership. It will not be used in any way for formal grading, ranking, or sanctions by the World Alliance of YMCAs or the Area Alliance. All information entered in this document is confidential and will be used exclusively for internal improvement and advisory purposes.
B16: Category Definitions
B17: The following is a description of what is evaluated in each category:
B19: Category | D19: Definition
B20: Financial Stability | D20: Reviews financial health, transparency, sustainability, and adherence to financial controls.
B21: Governance | D21: Evaluates leadership structure, decision-making transparency, and organisational accountability.
B22: Constitution / By-Laws / Policies / Procedures | D22: Evaluates whether the YMCA has a legally up-to-date and functional governance framework, and whether it is supported by clear, comprehensive policies and procedures. It also assesses the presence of key organizational policies that promote ethical governance, safety, inclusivity, transparency, accountability, and operational efficiency.
B23: Monitoring | D23: Evaluates how systematically the YMCA assesses the effectiveness and relevance of its programs and services. It also examines how well the YMCA captures and shares knowledge internally, ensuring continuous learning, accountability, and evidence-based improvement across the organization.
B24: Strategic Planning | D24: Assesses the existence, quality, and execution of long-term strategic and operational plans. It examines whether the organization has a current and participatory strategic plan, how often it is reviewed, and whether it includes innovation and alignment with the global Vision 2030 framework. It also assesses the clarity and consistency of the YMCA’s mission, vision, and values.
B25: Diversity and youth participation | D25: Checks how the YMCA promotes inclusive governance and engagement, particularly for young people and underrepresented groups. It examines whether the organization has formal provisions or policies ensuring diverse representation on its board.
B26: Communication and Branding | D26: Looks at the elements related to external communication and branding from the YMCA, including transparency and community accountability.
B27: Property Management | D27: Evaluates how the YMCA handles ownership, documentation, and strategic use of its physical assets. It looks at whether the organization owns property, ensures proper legal registration, manages risks related to property loss or disputes, and has a clear development or maintenance plan..
B28: Staff and volunteer development | D28: Assesses staff recruitment, development, retention policies, and workplace wellbeing practices.
B30: How to use the Tool
B32: General Instructions
B33: - Only modify the response cells (the designated answer boxes). - Do not alter the Excel file's structure, formulas, or any other elements. - If a question is not applicable, indicate "N/A" (Not Applicable) rather than leaving it blank. - If you are unsure how to answer a specific question, please seek clarification from your Area Alliance representative. - Consistency is essential: apply the same judgment standards across all areas. - Ensure no unintended changes have been made to non-response cells. - Submit the completed document to the Area Alliance.
B42: Score Criteria
B43: - The Score Criteria is calculated automatically based on your answers. - You do not need to manually assign or edit scores. - The scores are only indicative and should be treated only by taking in consideration the entire context of the organisation. For example, a low score on financial stability might not necessarily mean your YMCA has a very negative financial situation and when considering the score all other information needs to be analyzed as well.
B47: Who should fill this form?
B48: Gather a team of staff and volunteers across departments or functions of your organisation. The recommendation is to include your CEO/General Secretary, at least one board member (chair preferred), and other staff and volunteers representing the organization's key functions. However, only one final version that you all agree with should be shared with the Area Alliance.
B52: How to collect and collate responses?
B53: There are different options you might use (your choice): 1. Individuals complete the form. Share collated individual responses. Discuss and arrive at agreements during a meeting. 2. Complete the form as a group during a meeting of all stakeholders.
B55: How to finalize the Health Assessment?
B56: When your CEO/General Secretary and your President/Chair have agreed it, please submit it to your Area Alliance contact person.
B59: Data Protection
B60: By submitting this form, you acknowledge and agree to the following: 1. Access and Confidentiality: Your responses will be accessible to the Area Alliance and the World Alliance. All data provided will be handled with strict confidentiality by the Area Alliance, the World Alliance, and their authorized partners, in accordance with applicable data protection standards. 2.Data Sharing with Partners and Funders: Please tick the box below if you authorize the Area Alliance and the World Alliance to share your submitted data with trusted partners and potential funders for the purpose of strengthening humanitarian action, mobilizing support, and facilitating collaboration. Any shared data will be used responsibly and in alignment with privacy commitments.
B72: FALSE | C72: We authorize the Area Alliance and World Alliance to share the data of this health assessment partially or fully with trusted YMCA partners and/or potential funders for the purpose of strengthening humanitarian action, mobilising support, and facilitating collaboration.
B74: If you have questions or concerns about how your data is managed, please contact your Area Alliance contact person. If you have a concern that cannot be solved at that level, please contact the World YMCA Movement Strengthening/Strategy lead.

Sheet 1 General Information
A1: YMCA Annual Organisational Health Assessment Form
A2: Version 1.0 - 2026
B4: 1 | D4: GENERAL INFORMATION | E4: Please choose an option or fill the answer | F4: Additional Information | G4: Notes
B5: # | C5: Q101 | D5: Official/Legal Name of the YMCA | G5: This is the name in your Articles of Incorporation, Constitution or any other legal document recognized by the government of your country.
C6: Q102 | D6: Country
C7: Q103 | D7: Country code | G7: This will have been communicated to you. Leave the field blank if you do not know.
C8: Q104 | D8: Official/Legal address of the organisation
C9: Q105 | D9: Year or Period of Reporting | G9: Describe the reporting period (or, if more relevant, the month when you are filling this form), including Month/Date. For example, "Fiscal Year, October 2025 to September 2026".
B10: 1.1 | C10: Q106 | D10: Is your organisation officially registered as a nonprofit/non-governmental organisation (NGO)? | E10: Please choose an option
B11: 1.2 | C11: Q107 | D11: What is the official category of your organisation's registration according to your national regulations? (ex. Federation, Association, Foundation etc.)
B12: 1.3 | D12: Which of the following are applicable for your YMCA:
C13: Q108 | D13: - Tax-exempt status | E13: Please choose an option | G13: Any tax-exempt status counts. For example, property tax exemption, employer tax exemption, etc.
C14: Q109 | D14: - Special recognised status by the government (if applicable in your country, otherwise choose "Not applicable") | E14: Please choose an option
C15: Q110 | D15: - Other special designation or certification received by the organisation | E15: Please choose an option
C16: Q111 | D16: - Please give any further details here, if relevant (optional):
B17: 1.4 | C17: Q112 | D17: Is your organisation officially registered as a federative structure or a single entity ? | E17: Please choose an option
B18: 1.5 | C18: Q113 | D18: If a federated structure, how many member organisations do you have ?
C19: Q114 | D19: Number of member organisations registered as legal entities
C20: Q115 | D20: Number of informal groups or similar (not registered as legal entities)
C21: Q116 | D21: If there is any kind of a special situation, you can mention it here: | E21: Please write your answer here
B22: 1.6 | C22: Q117 | D22: Are any of your registered members currently inactive/dormant? If so, how many?
B23: 1.7 | C23: Q118 | D23: If a single entity, how many branches / sites do you have ?
B27: Category | D27: Your YMCA Score | E27: Maximum Possible Score | F27: Your percentage
B28: Financial Stability | D28: =SUM('2 Financial Stability'!E1:E52) | E28: 20 | F28: =(D28/E28)
B29: Governance | D29: =SUM('3 Governance'!E14:E31) | E29: 12 | F29: =(D29/E29)
B30: Constitution / By-laws / Policies / Procedures | D30: =SUM('4 Constitution, Bylaws, Polici'!E2:E23) | E30: 20 | F30: =(D30/E30)
B31: Monitoring & Evaluation | D31: =SUM('5 Monitoring & Evaluation'!E2:E11) | E31: 6 | F31: =(D31/E31)
B32: Strategic Planning | D32: =SUM('6 Strategic Planning & Mission'!E2:E24) | E32: 12 | F32: =(D32/E32)
B33: Diversity and Youth Participation | D33: =SUM('7 Diversity & Youth Participati'!E4:E9) | E33: 4 | F33: =(D33/E33)
B34: Communications & Branding | D34: =SUM('8 Communications & Branding'!E2:E7) | E34: 5 | F34: =(D34/E34)
B35: Property Management | D35: N/A | E35: N/A | F35: N/A
B36: Staff and Volunteer Development | D36: =SUM('10 Staff+Volunteer Development'!E2:E8) | E36: 5 | F36: =(D36/$E$36)
B37: TOTAL SCORE | D37: =SUM(D28:D36) | E37: =SUM(E28:E36) | F37: =(D37/E37)
B39: SUBMISSION
B40: Who participated in completing this questionnaire ?
B41: Chair/ President of the Board | D41: Please choose an option
B42: NGS | D42: Please choose an option
B43: Key Staff | D43: Please choose an option
B44: National Board | D44: Please choose an option

Sheet 2 Financial Stability
A1: 2 | C1: FINANCIAL STABILITY | D1: Please choose an option or fill the answer | E1: Scoring | F1: Additional Information | G1: Notes
A2: 2.1 | B2: Q201 | C2: Do you you have an Annual Financial Plan or Budget? | D2: Please choose an option | E2: =IF(D2="Yes", 1, IF(D2="No", 0, ""))
A3: 2.2 | B3: Q202 | C3: Do you report on actual results against Plan or Budget? (eg. producing financial reports) | D3: Please choose an option | E3: =IF(D3="Yes", 1, IF(D3="No", 0, ""))
A4: 2.3 | C4: What type of audit is your YMCA doing annually? | G4: Please enter year of last report in Additional Information:
B5: Q203 | C5: - Minimum internal controls mandated by the national legislation and/or your YMCA's policies | D5: Please choose an option | E5: =IF(D5="Yes", 1, IF(D5="No", 0, ""))
B6: Q204 | C6: - Project-based audits performed by the funders (eg. state audits, external audits etc.) for grants received | D6: Please choose an option | E6: =IF(D6="Yes", 1, IF(D6="No", 0, ""))
B7: Q205 | C7: - A comprehensive annual audit performed by an independent audit company or professional | D7: Please choose an option | E7: =IF(D7="Yes", 1, IF(D7="No", 0, ""))
A8: 2.4 | B8: Q206 | C8: If your organisation uses the services of an audit company or professional, for how many years have you been using their services? Please mention in additional information alongside if there is any policy to rotate the auditors. | D8: Please choose an option | E8: =IF(D8="1 - 5 years",1,"") | G8: Generally, it is considered a good practice to change the auditors in order to ensure objectivity and a more neutral attitude. For example, some YMCAs are changing auditors every 3 or 4 years.
A9: 2.5 | B9: Q207 | C9: Is the Annual Financial Report public? (e.g. published on your website as part of your annual report or separately) | D9: Please choose an option | E9: =IF(D9="Yes", 1, IF(D9="No", 0, ""))
A10: 2.6 | B10: Q208 | C10: What currency does your YMCA use? (e.g., Euro, Peso etc) | E10: N/A
A11: 2.7 | B11: Q209 | C11: What is the total value of your current assets? (Numeric value only e.g., 10 005) | E11: N/A | G11: If you are a National YMCA, please refer to the value of your national federation/entity only.
A12: 2.8 | B12: Q210 | C12: What is the total value of your current liabilities? (Numeric value only) | E12: N/A | G12: If you are a National YMCA, please refer to the value of your national federation/entity only.
A13: 2.9 | B13: Q211 | C13: What is the total value of your income in the past financial year? (Numeric value only) | E13: N/A | G13: If you are a National YMCA, please refer to the value of your national federation/entity only.
A14: 2.1 | B14: Q212 | C14: What is the total value of your expenditure in the past financial year? (Numeric value only) | E14: N/A | G14: If you are a National YMCA, please refer to the value of your national federation/entity only.
A15: 2.11 | B15: Q213 | C15: What is the operating balance (deficit, surplus) in the year under review? (Numeric value only) | D15: =D13-D14 | E15: N/A | G15: If you are a National YMCA, please refer to the value of your national federation/entity only.
A16: 2.12 | C16: For the items listed below, what is the estimated percentage of the total amount of generated income in the past financial year? Enter as a numeric value (For example, for 25% enter 25). | D16: %
B17: Q214 | C17: - Paid Services offered by your YMCA to various clients (business activities, including social entrepreneurship) | E17: =IF(COUNTA(D17:D25)=0,"", IF(MAX(D17:D25)>65,0, IF(MAX(D17:D25)>=50,1, 2))) | F17: =IF(COUNTA(D17:D25)=0, "", IF(MAX(D17:D25)>65, " It seems that your YMCA is highly dependent on 1 major source of income. This might pose a significant risk to the sustainability of your YMCA. It is strongly recommended that you aim to diversify your income sources in the next 3–5 years.", IF(COUNTIFS(D17:D25, ">=50", D17:D25, "<=65")>0, " It seems that your YMCA has a relatively high reliance on a major source of income. In order to reduce potential risks it is recommended that you try to diversify your income sources, if possible.", "") ))
B18: Q215 | C18: - Government subsidies (excluding project grants)
B19: Q216 | C19: - Membership fees / Fair Share
B20: Q217 | C20: - Individual donations
B21: Q218 | C21: - Sponsorship from private companies
B22: Q219 | C22: - Public grants (from local, national government, European Union, United Nations etc.)
B23: Q220 | C23: - Private grants (from companies, private entities, foundations etc.) excluding YMCA funding
B24: Q221 | C24: - YMCA Grants or similar support from other YMCAs outside your country
B25: Q222 | C25: - Other
A26: 2.13 | C26: Out of your annual income, what is the percentage of national/local versus international funding? Enter as a numeric value (For example, for 25% enter 25). | D26: %
B27: Q223 | C27: - Local / National sources | E27: =IF(D28 ="","", IF(D28>75,0,1)) | F27: =IF(D28>75, "It seems that your YMCA has a high reliance on international sources of funds. Depending on your context, this can pose a risk. Please consider if diversification of funding sources can be feasible for your YMCA in the next 3–5 years.", "")
B28: Q224 | C28: - International sources
A29: 2.14 | C29: Out of your annual income, what is the percentage of restricted versus unrestricted funding? Enter as a numeric value (For example, for 25% enter 25). | D29: %
B30: Q225 | C30: - Restricted funding (e.g. where the funding has to be spent on specific activities, outcomes etc.) | E30: =IF(D30="", "", IF(D30<85, 1, 0)) | F30: =IF(D30>85, " It seems that your YMCA is highly reliant on restricted funding. It is recommended that you aim to achieve a higher proportion of unrestricted funding for your YMCA " & "in the next 3–5 years in order to increase your sustainability, independence and build a stronger reserve.", "")
B31: Q226 | C31: - Unrestricted funding (eg. where you decide where to allocate that amount of money)
A32: 2.15 | B32: Q227 | C32: If one of your major funders/partners would stop their funding in the next 6 months, would that affect your YMCA dramatically? | D32: Please choose an option | E32: =IF(D32="Yes", 0, IF(D32="No", 1, ""))
B33: Q228 | C33: Do you have any backup / risk mitigation plan to limit the negative impact of such a limitation? | D33: Please choose an option | E33: =IF(D33="Yes", 1, IF(D33="No", 0, ""))
A34: 2.16 | C34: For the items listed below, what is the percentage of your total expenditure? Enter as a numeric value (For example, for 25% enter 25). | D34: %
B35: Q229 | C35: - Programmes delivery | E35: N/A
B36: Q230 | C36: - Internal Meetings
B37: Q231 | C37: - Salaries of Staff (including taxes, social contributions)
B38: Q232 | C38: - Property maintenance
B39: Q233 | C39: - Business services
B40: Q234 | C40: - Membership fees to other Associations/Federations
...

Sheet 3 Governance
A1: 3 | C1: GOVERNANCE | D1: Please choose an option or fill the answer | E1: Scoring | F1: Additional Information | G1: Notes
A2: 3.1 | B2: Q310 | C2: Which is the ultimate decision-making body of your YMCA? | D2: Please choose an option | E2: N/A | G2: Based on your Constitution / Statutes or by law, each nonprofit organisation has a decision-making body that is considered the most important. For Associations of Federations, this is usually the General Assembly.
B3: Q311 | C3: If you chose "Other", please explain here | E3: N/A
A4: 3.2 | B4: Q312 | C4: Who elects the Board in your YMCA? | E4: N/A | G4: Depending on how your YMCA is structured legally, this can be your General Assembly, the Board itself or other mechanisms.
A5: 3.3 | C5: What is the minimum and the maximum number of Board Members that your YMCA can have in accordance to the constitution/statute?
B6: Q313 | C6: - Minimum number of board members | E6: N/A
B7: Q314 | C7: - Maximum number of board members | E7: N/A
A8: 3.4 | C8: Total Number of current Board Members
B9: Q315 | C9: - Females - Number | E9: N/A
B10: Q316 | C10: - Males - Number | E10: N/A
B11: Q317 | C11: - Non-binary - Number | E11: N/A
B12: Q318 | C12: - Under 30 - Number | E12: N/A
B13: Q319 | C13: - Serving in the board for the first time - Number | E13: N/A
A14: 3.5 | B14: Q320 | C14: Is your YMCA recruiting/electing your board based on the skills that are required to implement your strategy? | D14: Please choose an option | E14: =IF(D14="Yes", 1, IF(D14="No", 0, "")) | G14: Several YMCAs might be analyzing what kind of people they need in their Board based on the skills that are needed. For example, if the priority of the YMCA is to raise more funds, maybe a person with fundraising experience or connections might be valuable for the Board. Many YMCAs might be performing a needs assessment to analyze the required skills and then recruit accordingly.
B15: Q321 | C15: If yes, please indicate what approach you are using | E15: N/A
A16: 3.6 | B16: Q322 | C16: What is the standard duration of the term of your Board Members and President/Chair? (in years) | E16: =IF(D16="", "", IF(D16>=5, 0, 1)) | G16: Based on your Constitution / Statutes
A17: 3.7 | C17: Is there a limit to how many terms a Board Member and your President/Chair can serve? If so, which is the limit?
B18: Q323 | C18: - Board Members | D18: Please choose an option | E18: =IF(D18="Yes", 1, IF(D18="No", 0, ""))
B19: Q324 | C19: Term limit in years | E19: N/A
B20: Q325 | C20: - President / Chair | D20: Please choose an option | E20: =IF(D20="Yes", 1, IF(D20="No", 0, ""))
B21: Q326 | C21: Term limit in years | E21: N/A
A22: 3.8 | B22: Q325 | C22: Does the Board carry out an annual evaluation of its performance? | D22: Please choose an option | E22: =IF(D22="Yes", 1, IF(D22="No", 0, ""))
A23: 3.9 | B23: Q326 | C23: How many times did the Board meet in the previous year? | D23: Please choose an option | E23: =IF(D23="2 or more times",1, IF(OR(D23="None",D23="1 time"),0, ""))
A24: 3.1 | B24: Q327 | C24: Does the Board evaluate the performance of the CEO / General Secretary annually? | D24: Please choose an option | E24: =IF(D24="Yes", 1, IF(D24="No", 0, ""))
A25: 3.11 | B25: Q328 | C25: Are the CEO/General Secretary and the President/Chair two different people? | D25: Please choose an option | E25: =IF(D25="Yes", 1, IF(D25="No", 0, ""))
A26: 3.12 | B26: Q329 | C26: Is there a CEO/General Secretary succession plan? (temporary + long-term succession) | D26: Please choose an option | E26: N/A | G26: A succession plan refers to the way your YMCA responds when your leadership (CEO, Secretary General etc.) is temporarily or permanently unable to do their job, for any reason (eg. accident, death, illness, retirement etc.). By having a succession plan the organisation already decided what to do in case this happens. Also, the succession plan can refer to how the next leaders are being prepared so that the next generation can be ready to take the leadership when the time comes.
B27: Q330 | C27: Temporary Succession Plan (eg. emergency situations, unforeseen situations) | D27: Please choose an option | E27: =IF(D27="Yes", 1, IF(D27="No", 0, ""))
B28: Q331 | C28: Long-term Succession Plan | D28: Please choose an option | E28: =IF(D28="Yes", 1, IF(D28="No", 0, ""))
A29: 3.13 | C29: Does your YMCA have insurance policies for all your key properties/assets and management risks (eg. board liability)?
B30: Q332 | C30: - Key properties / assets | D30: Please choose an option | E30: =IF(D30="Yes", 1, IF(D30="No", 0, ""))
B31: Q333 | C31: - Management risks / liability | D31: Please choose an option | E31: =IF(D31="Yes", 1, IF(D31="No", 0, ""))
A33: Total Score | D33: =SUM(E14:E31)
A34: Maximum Possible Score | D34: 12 points
A35: Comments / Observations | D35: OPTIONAL
A36: Based on this assessment, which areas of improvement/changes would you like your YMCA to work towards in the next year for this category?

Sheet 4 Constitution, Bylaws, Polici
A1: 4 | C1: CONSTITUTION / BYLAWS / POLICIES / PROCEDURES | D1: Please choose an option or fill the answer | E1: Scoring | F1: Additional Information | G1: Notes
A2: 4.1 | B2: Q410 | C2: Is your constitution/statute up to date with the latest requirements in your country? | D2: Please choose an option | E2: =IF(D2="Yes", 1, IF(D2="No", 0, ""))
A3: 4.2 | B3: Q411 | C3: Is there a plan to make a meaningful change to your constitution/statute in the next year? | D3: Please choose an option | E3: N/A | G3: Are you planning to change your key documents in a very important way? For example, making changes to how decisions are made, how the Board is elected, changing your mission etc.
A4: 4.3 | C4: Do the following policies exist and are they applied:
B5: Q412 | C5: - Conflict of Interest Policy | D5: Please choose an option | E5: =IF(D5="Yes", 1, IF(D5="No", 0, ""))
B6: Q413 | C6: - Safeguarding Policy (including but not limited to Child Protection or similar) | D6: Please choose an option | E6: =IF(D6="Yes", 1, IF(D6="No", 0, "")) | G6: Safeguarding refers to the rules you have in place in your YMCA to protect children, young people and adults from sexual abuse or any other type of harrassment and mental or physical abuse. For example, a YMCA that organises summer camps should normally have rules in place to ensure the safety of everyone attending, especially those who are vulnerable to abuse.
B7: Q414 | C7: - Whistleblowing Policy (Grievance Procedure etc.) or mechanism | D7: Please choose an option | E7: =IF(D7="Yes", 1, IF(D7="No", 0, "")) | G7: A "whistleblowing" policy refers to the situations where someone might file a complaint against the leadership of your YMCA and where there is a clear need for them to be protected against persecution. For example, a staff member filing a complaint against the Secretary General to the YMCA's President/Chair. It is important that the complaint is taken seriously and that the person complaining is protected, and maybe that it remains anonymous (so the Secretary General is not informed who made the complaint). This can create a safer work environment, where staff and volunteers feel that they can voice their concerns without being punished for it.
B8: Q415 | C8: - Diversity, Equity and Inclusion Policy (including any Anti-Discrimination Policy) | D8: Please choose an option | E8: =IF(D8="Yes", 1, IF(D8="No", 0, ""))
B9: Q416 | C9: - Health & Safety Policy | D9: Please choose an option | E9: =IF(D9="Yes", 1, IF(D9="No", 0, "")) | G9: This can refer to the measures you are taking to ensure the physical and mental health of your staff and volunteers.
B10: Q417 | C10: - Personnel/HR Policy | D10: Please choose an option | E10: =IF(D10="Yes", 1, IF(D10="No", 0, ""))
B11: Q418 | C11: - Financial Procedures Manual/Handbook | D11: Please choose an option | E11: =IF(D11="Yes", 1, IF(D11="No", 0, ""))
B12: Q419 | C12: - Gift Acceptance Policy | D12: Please choose an option | E12: =IF(D12="Yes", 1, IF(D12="No", 0, "")) | G12: The policy through which you decide if your YMCA's leadership can receive gifts from others and for which amounts. This is important, because gifts can also lead to influence and potential corruption.
B13: Q420 | C13: - Cybersecurity / Artificial Intelligence Policy | D13: Please choose an option | E13: =IF(D13="Yes", 1, IF(D13="No", 0, ""))
B14: Q421 | C14: - Data Protection and Privacy Policy | D14: Please choose an option | E14: =IF(D14="Yes", 1, IF(D14="No", 0, ""))
B15: Q422 | C15: - Procurement Policy/Procedure | D15: Please choose an option | E15: =IF(D15="Yes", 1, IF(D15="No", 0, "")) | G15: This refers to the rules on how your YMCA buys services and products. For example, for transactions above a certain value you can decide you need stricter rules (eg. asking for more offers instead of buying directly from 1 supplier).
B16: Q423 | C16: - Board Nomination / Election Procedure | D16: Please choose an option | E16: =IF(D16="Yes", 1, IF(D16="No", 0, ""))
B17: Q424 | C17: - Membership Criteria (for federated structures) | D17: Please choose an option | E17: =IF(D17="Yes", 1, IF(D17="No", 0, ""))
B18: Q425 | C18: - Code of Conduct for Board Members | D18: Please choose an option | E18: =IF(D18="Yes", 1, IF(D18="No", 0, ""))
B19: Q426 | C19: - Code of Conduct for Staff Members and Volunteers | D19: Please choose an option | E19: =IF(D19="Yes", 1, IF(D19="No", 0, ""))
B20: Q427 | C20: - Staff and Volunteers Wellbeing and professional development policies or procedures | D20: Please choose an option | E20: =IF(D20="Yes", 1, IF(D20="No", 0, ""))
B21: Q428 | C21: - Climate Sustainability Policies (eg. carbon reduction policies, carbon audits etc.) | D21: Please choose an option | E21: =IF(D21="Yes", 1, IF(D21="No", 0, ""))
B22: Q429 | C22: - Anti-corruption Policy | D22: Please choose an option | E22: =IF(D22="Yes", 1, IF(D22="No", 0, ""))
B23: Q430 | C23: - Risk Management Policy/Plan | D23: Please choose an option | E23: =IF(D23="Yes", 1, IF(D23="No", 0, ""))
B24: Q431 | C24: - Other relevant policies (which can also serve as best practices)
A26: Total Score | D26: =SUM(E2:E23)
A27: Maximum Possible Score | D27: 20 points
A28: Comments / Observations | D28: OPTIONAL
A29: Based on this assessment, which areas of improvement/changes would you like your YMCA to work towards in the next year for this category?

Sheet 5 Monitoring & Evaluation
A1: 5 | C1: MONITORING & EVALUATION | D1: Please choose an option or fill the answer | E1: Scoring | F1: Additional Information | G1: Notes
A2: 5.1 | C2: Does your YMCA monitor and evaluate the quality of the services/programmes you provide to your target-groups/community? | G2: This question seeks to determine if your YMCA has a formal way of checking if your programs are actually working and meeting the needs of your community. It distinguishes between doing this "only when necessary" versus "as a standard rule."
B3: Q511 | C3: Project-based or when required by the partners / donors / funders | D3: Please choose an option | E3: =IF(D3="Yes", 1, IF(D3="No", 0, "")) | G3: This refers to occasional evaluation. Select this if monitoring is only performed for specific initiatives or when requested by external funders for a particular grant/project.
B4: Q512 | C4: Systemically, through dedicated organisation-wide processes (eg. across all the projects and activities of your YMCA) | D4: Please choose an option | E4: =IF(D4="Yes", 1, IF(D4="No", 0, "")) | G4: This refers to permanent evaluation. Select this if your YMCA has established internal procedures to consistently measure the quality of all programs and services across the entire organization.
A5: 5.2 | C5: Do you run needs assessment of your target groups/members periodically? | F5: Please write how often here
B6: Q513 | C6: - Project-based or when required by the partners / donors / funders | D6: Please choose an option | E6: =IF(D6="Yes", 1, IF(D6="No", 0, "")) | G6: You only conduct research when starting a new specific project or because a donor asks for it.
B7: Q514 | C7: - Systemically, through dedicated organisation-wide processes (eg. across all the projects and activities of your YMCA) | D7: Please choose an option | E7: =IF(D7="Yes", 1, IF(D7="No", 0, "")) | G7: Your YMCA has a fixed schedule or a permanent department that researches community needs regardless of specific funding.
A8: 5.3 | B8: Q515 | C8: Do you have mechanisms to record knowledge and experience, and make it accessible throughout the organisation? | D8: Please choose an option | E8: =IF(D8="Yes", 1, IF(D8="No", 0, "")) | G8: This refers to any knowledge management mechanism, platform or tool that you have. For example, to ensure best practices / information remains in your organisation even after some staff members leave or move to other areas of work. A specific case can be, for example, on camping knowledge. The tools, methods used, lessons learned can be made accessible to future camp leaders.
A9: 5.4 | B9: Q516 | C9: Does your YMCA use impact measurement tools? | D9: Please choose an option | E9: =IF(D9="Yes", 1, IF(D9="No", 0, "")) | G9: Does your YMCA use specific methodologies or software to track long-term change? (Examples: surveys, Social Return on Investment (SROI), specialized software, or focus groups).
B10: Q517 | C10: If yes, which ones: | E10: N/A
A11: 5.5 | B11: Q518 | C11: What is the total approximate number of beneficiaries that your YMCA reaches in a year (on average)? | E11: N/A
A14: Total Score | D14: =SUM(E3:E9)
A15: Maximum Possible Score | D15: 6 points
A16: Comments / Observations | D16: OPTIONAL
A17: Based on this assessment, which areas of improvement/changes would you like your YMCA to work towards in the next year for this category?

Sheet 6 Strategic Planning & Mission
A1: 6 | C1: STRATEGIC PLANNING & MISSION | D1: Please choose an option or fill the answer | E1: Scoring | F1: Additional Information
A2: 6.1 | B2: Q610 | C2: Does your National Movement have a Strategic Plan? | D2: Please choose an option | E2: =IF(D2="Yes", 3, IF(D2="No", 0, ""))
B3: Q611 | C3: When did you adopt your current Strategic Plan and for what duration/years/period? | E3: N/A
A4: 6.2 | C4: Who participates in the formulation of the Strategic Plan:
B5: Q612 | C5: - Staff | D5: Please choose an option | E5: =IF(D5="Yes", 1, IF(D5="No", 0, ""))
B6: Q613 | C6: - Board Members | D6: Please choose an option | E6: =IF(D6="Yes", 1, IF(D6="No", 0, ""))
B7: Q614 | C7: - Members | D7: Please choose an option | E7: =IF(D7="Yes", 1, IF(D7="No", 0, ""))
B8: Q615 | C8: - Volunteers | D8: Please choose an option | E8: =IF(D8="Yes", 1, IF(D8="No", 0, ""))
B9: Q616 | C9: - Target-groups / Beneficiaries / Young people / Community | D9: Please choose an option | E9: =IF(D9="Yes", 1, IF(D9="No", 0, ""))
B10: Q617 | C10: - Other partners (government, business, other relevant partners for your YMCA) | E10: N/A
A11: 6.3 | B11: Q618 | C11: Do you revise / update your Strategic Plan annually to ensure it is still relevant? | D11: Please choose an option | E11: =IF(D11="Yes", 1, IF(D11="No", 0, ""))
A12: 6.4 | B12: Q619 | C12: Does your Strategic Plan have an innovation component? (does your YMCA aim to innovate in at least one area, such as programmes, operations, advocacy methods etc.?) | D12: Please choose an option | E12: =IF(D12="Yes", 1, IF(D12="No", 0, ""))
A13: 6.5 | B13: Q620 | C13: Is Vision 2030 reflected in your Strategic Plan? | D13: Please choose an option | E13: =IF(D13="Yes", 1, IF(D13="No", 0, ""))
A14: 6.6 | C14: If yes, which of the following Vision 2030 components have been covered in your Strategic Plan?
B15: Q621 | C15: - Collective Vision | D15: Please choose an option | E15: N/A
B16: Q622 | C16: - Collective Mission | D16: Please choose an option
B17: Q623 | C17: - Pillar 1: Community Wellbeing | D17: Please choose an option
B18: Q624 | C18: - Pillar 2: Meaningful Work | D18: Please choose an option
B19: Q625 | C19: - Pillar 3: Sustainable Planet | D19: Please choose an option
B20: Q626 | C20: - Pillar 4: Just World | D20: Please choose an option
B21: Q627 | C21: - Vision 2030 Strategic Goals | D21: Please choose an option
A22: 6.7 | B22: Q628 | C22: What is your YMCA's vision and mission? | E22: N/A
A23: 6.8 | B23: Q629 | C23: What are your YMCA's values? | E23: N/A
A24: 6.9 | B24: Q630 | C24: Mission and Values are aligned (don't contradict) with the Christian values of the YMCA Movement (regardless of how this is expressed in writing) | D24: Please choose an option | E24: =IF(D24="Yes", 1, IF(D24="No", 0, ""))
A25: 6.1 | C25: Do you have the following World YMCA Foundational and Fundamental Statements mentioned in your constitution, by-laws or similar statements?
B26: Q631 | C26: - Paris Basis | D26: Please choose an option | E26: N/A
B27: Q632 | C27: - Kampala Principles | D27: Please choose an option
B28: Q633 | C28: - Challenge 21 | D28: Please choose an option
B29: Q634 | C29: - Nairobi Statement | D29: Please choose an option
B30: Q635 | C30: - World YMCA Value Statement | D30: Please choose an option
A32: Total Score | D32: =SUM(E2:E30)
A33: Maximum Possible Score | D33: 12 points
A34: Comments / Observations | D34: OPTIONAL
A35: Based on this assessment, which areas of improvement/changes would you like your YMCA to work towards in the next year for this category?

Sheet 7 Diversity & Youth Participati
A1: 7 | C1: DIVERSITY AND YOUTH PARTICIPATION | D1: Please choose an option or fill the answer | E1: Scoring | F1: Additional Information
A2: 7.1 | B2: Q710 | C2: Is your YMCA open to any person, regardless of age, gender, religion, sexual orientation, economic background, ethnicity, political views, migration status etc.? | D2: Please choose an option | E2: =IF(D2="Yes", 1, IF(D2="No", 0, ""))
A3: 7.2 | C3: Is there any provision in your constitution / statute / by-laws (or any other similar systems) regarding the following diversity and inclusion criteria (eg. minimum 30% of the board members should be under 30 years old, more than 50% should not be from the same gender etc.)
B4: Q711 | C4: - Young people representation (as defined by your YMCA) | D4: Please choose an option | E4: =IF(D4="Yes", 1, IF(D4="No", 0, ""))
B5: Q712 | C5: - Gender representation | D5: Please choose an option | E5: =IF(D5="Yes", 1, IF(D5="No", 0, ""))
B6: Q713 | C6: - Other dimensions, if relevant (eg. indigenous communities, geographical etc.) | D6: Please choose an option | E6: N/A | F6: Please detail:
A7: 7.3 | B7: Q714 | C7: Is there any procedure or initiative to ensure the equal participation of your board members regardless of background or experience? | D7: Please choose an option | E7: =IF(D7="Yes", 1, IF(D7="No", 0, ""))
B8: Q715 | C8: If yes, please give more details: | E8: N/A
A9: 7.4 | B9: Q716 | C9: Do you have any other policies and/or systems in place to ensure the equal participation and inclusion of young people, volunteers, staff members in the activities of your YMCA? | D9: Please choose an option | E9: =IF(D9="Yes", 1, IF(D9="No", 0, ""))
B10: Q717 | C10: If yes, please give more details: | E10: N/A
A12: Total Score | D12: =SUM(E4:E9)
A13: Maximum Possible Score | D13: 4 points
A14: Comments / Observations | D14: OPTIONAL
A15: Based on this assessment, which areas of improvement/changes would you like your YMCA to work towards in the next year for this category?

Sheet 8 Communications & Branding
A1: 8 | C1: COMMUNICATIONS AND BRANDING | D1: Please choose an option or fill the answer | E1: Scoring | F1: Additional Information
A2: 8.1 | B2: Q810 | C2: Does your YMCA produce and publish an Annual Report which is available publicly? | D2: Please choose an option | E2: =IF(D2="Yes", 1, IF(D2="No", 0, ""))
A3: 8.2 | B3: Q811 | C3: Does your YMCA have a website that is regularly kept up to date? | D3: Please choose an option | E3: =IF(D3="Yes", 1, IF(D3="No", 0, ""))
A4: 8.3 | B4: Q812 | C4: Does your YMCA have a communications strategy? | D4: Please choose an option | E4: =IF(D4="Yes", 1, IF(D4="No", 0, ""))
A5: 8.4 | B5: Q813 | C5: Does your YMCA have a dedicated staff or volunteer on communications and/or public relations? | D5: Please choose an option | E5: =IF(D5="Yes", 1, IF(D5="No", 0, ""))
A6: 8.5 | B6: Q814 | C6: Is the brand/logo/trademark of your YMCA legally registered and protected by your national legislation? | D6: Please choose an option | E6: =IF(D6="Yes", 1, IF(D6="No", 0, ""))
A7: 8.6 | B7: Q815 | C7: (For Federations only) Does your national YMCA have licensing agreements with your member YMCAs which describe how the brand can be used (including provisions regarding what happens if the member leaves the federation)? | E7: N/A
A9: Total Score | D9: =SUM(E1:E6)
A10: Maximum Possible Score | D10: 5 points
A11: Comments / Observations | D11: OPTIONAL
A12: Based on this assessment, which areas of improvement/changes would you like your YMCA to work towards in the next year for this category?

Sheet 9 Property Management
A1: 9 | C1: PROPERTY MANAGEMENT | D1: Please choose an option or fill the answer | E1: Scoring | F1: Additional Information
A2: 9.1 | B2: Q910 | C2: Does your organisation have any property that it owns? (eg. buildings, land, vehicles, stocks, bonds, other investments etc.) | D2: Please choose an option | E2: N/A
B3: Q911 | C3: If yes, please list them: | E3: N/A
A4: 9.2 | B4: Q912 | C4: Are your properties properly registered and documented? | D4: Please choose an option | E4: N/A
A5: 9.3 | B5: Q913 | C5: Do you have any risks that might lead to the loss of the property or other similar negative outcomes? | D5: Please choose an option | E5: N/A
B6: Q914 | C6: If yes, please detail: | E6: N/A
A7: 9.4 | B7: Q915 | C7: Do you have a property development plan? | D7: Please choose an option | E7: N/A
A9: Comments / Observations | D9: OPTIONAL
A10: Based on this assessment, which areas of improvement/changes would you like your YMCA to work towards in the next year for this category?

Sheet 10 Staff+Volunteer Development
A1: 10 | C1: STAFF AND VOLUNTEER DEVELOPMENT | D1: Please choose an option or fill the answer | F1: Additional information
A2: 10.1 | B2: Q1001 | C2: Do you have enough volunteers to deliver your operational plan? | D2: Please choose an option | E2: =IF(D2="Yes", 1, IF(D2="No", 0, ""))
A3: 10.2 | B3: Q1002 | C3: Do you have enough staff people to deliver your operational plan? | D3: Please choose an option | E3: =IF(D3="Yes", 1, IF(D3="No", 0, ""))
A4: 10.3 | B4: Q1003 | C4: Do you have an effective system of staff and volunteers training? | D4: Please choose an option | E4: =IF(D4="Yes", 1, IF(D4="No", 0, ""))
A5: 10.4 | B5: Q1004 | C5: Are all employees officially hired? | D5: Please choose an option | E5: =IF(D5="Yes", 1, IF(D5="No", 0, ""))
B6: Q1005 | C6: Do your employees benefit from social security/pension/health insurance? If yes, please give details if relevant. | E6: N/A
B7: Q1006 | C7: Please provide any additional context, if needed (eg. consultants, flexible work schemes etc) | E7: N/A
A8: 10.5 | B8: Q1007 | C8: Is there a job description for each position? | D8: Please choose an option | E8: =IF(D8="Yes", 1, IF(D8="No", 0, ""))
A9: 10.6 | B9: Q1008 | C9: Total number of current staff in your YMCA | E9: N/A
A10: 10.7 | B10: Q1009 | C10: Permanent / Core staff - Number
B11: Q1010 | C11: Temporary / Seasonal - Number
B12: Q1011 | C12: Project-based staff - Number
B13: Q1012 | C13: Under 30 - Number
B14: Q1013 | C14: Total number of current volunteers in your YMCA
A16: Total Score | D16: =SUM(E2:E8)
A17: Maximum Possible Score | D17: 5 points
A18: Comments / Observations | D18: OPTIONAL
A19: Based on this assessment, which areas of improvement/changes would you like your YMCA to work towards in the next year for this category?

Sheet Scores
A1: Category | B1: YMCA Score | C1: Maximum Score | D1: Status | E1: Percentage | G1: Range
A2: ='1 General Information'!B28 | B2: ='1 General Information'!D28 | C2: 20 | D2: =IF(E2>=0.9,"Excellent", IF(E2>=0.7,"Strong", IF(E2>=0.5,"Developing", IF(E2>=0.2,"At Risk",IF(E2>=0.01, "Critical","Not started"))))) | E2: =IF(C2="","",B2/C2) | G2: 90% - 100%
A3: ='1 General Information'!B29 | B3: ='1 General Information'!D29 | C3: ='1 General Information'!E29 | D3: =IF(E3>=0.9,"Excellent", IF(E3>=0.7,"Strong", IF(E3>=0.5,"Developing", IF(E3>=0.2,"At Risk",IF(E3>=0.01, "Critical","Not started"))))) | E3: =IF(C3="","",B3/C3) | G3: 70% - 89%
A4: ='1 General Information'!B30 | B4: ='1 General Information'!D30 | C4: ='1 General Information'!E30 | D4: =IF(E4>=0.9,"Excellent", IF(E4>=0.7,"Strong", IF(E4>=0.5,"Developing", IF(E4>=0.2,"At Risk",IF(E4>=0.01, "Critical","Not started"))))) | E4: =IF(C4="","",B4/C4) | G4: 50% - 69%
A5: ='1 General Information'!B31 | B5: ='1 General Information'!D31 | C5: ='1 General Information'!E31 | D5: =IF(E5>=0.9,"Excellent", IF(E5>=0.7,"Strong", IF(E5>=0.5,"Developing", IF(E5>=0.2,"At Risk",IF(E5>=0.01, "Critical","Not started"))))) | E5: =IF(C5="","",B5/C5) | G5: 20% - 49%
A6: ='1 General Information'!B32 | B6: ='1 General Information'!D32 | C6: ='1 General Information'!E32 | D6: =IF(E6>=0.9,"Excellent", IF(E6>=0.7,"Strong", IF(E6>=0.5,"Developing", IF(E6>=0.2,"At Risk",IF(E6>=0.01, "Critical","Not started"))))) | E6: =IF(C6="","",B6/C6) | G6: 1% - 19%
A7: ='1 General Information'!B33 | B7: ='1 General Information'!D33 | C7: ='1 General Information'!E33 | D7: =IF(E7>=0.9,"Excellent", IF(E7>=0.7,"Strong", IF(E7>=0.5,"Developing", IF(E7>=0.2,"At Risk",IF(E7>=0.01, "Critical","Not started"))))) | E7: =IF(C7="","",B7/C7) | G7: Not started
A8: Communications & Branding | B8: ='1 General Information'!D34 | C8: 5 | D8: =IF(E8>=0.9,"Excellent", IF(E8>=0.7,"Strong", IF(E8>=0.5,"Developing", IF(E8>=0.2,"At Risk",IF(E8>=0.01, "Critical","Not started"))))) | E8: =IF(C8="","",B8/C8)
A9: ='1 General Information'!B36 | B9: ='1 General Information'!D36 | C9: ='1 General Information'!E36 | D9: =IF(E9>=0.9,"Excellent", IF(E9>=0.7,"Strong", IF(E9>=0.5,"Developing", IF(E9>=0.2,"At Risk",IF(E9>=0.01, "Critical","Not started"))))) | E9: =IF(C9="","",B9/C9)
A11: Overall Percentage | B11: =IF(A12>=0.9, "Your YMCA demonstrates excellent organizational health across all key areas. Keep building on these strengths.", IF(A12>=0.7, "Your YMCA shows strong organizational health, with a few opportunities to further strengthen impact.", IF(A12>=0.5, "Your YMCA is developing organizational capacity, with clear opportunities for targeted strengthening.", IF(A12>=0.2, "Your YMCA faces challenges in several areas and would benefit from focused support and planning.",IF(A12>=0.01, "Your YMCA is experiencing critical organizational challenges that require immediate attention and support.","Not started"))))) | G11: Priority Areas
A12: =SUM(B2:B9) / SUM(C2:C9) | G12: {=IFERROR( INDEX($A$2:$A$9, MATCH( SMALL(IF($E$2:$E$9<0.5,$E$2:$E$9),1), $E$2:$E$9, 0) ), "" )}
A13: =IF(A12>=0.9,"Excellent Organizational Health", IF(A12>=0.7,"Strong Organizational Health", IF(A12>=0.5,"Developing Organizational Health", IF(A12>=0.2,"At Risk Organizational Health",IF(A12>=0.001,"Critical Organizational Health", "Not started"))))) | G13: {=IFERROR( INDEX($A$2:$A$9, MATCH( SMALL(IF($E$2:$E$9<0.5,$E$2:$E$9),2), $E$2:$E$9, 0) ), "" )}
